Workbook

Sheet Instructions
A1: Legacy Assessment Framework v1.0 — How to use this workbook
A3: Purpose
B4: This workbook operationalises the Legacy Assessment Framework. It scores a component across thirty-five tests grouped under seven headings of optionality, rolls those tests up to a heading rating, then rolls components up to a system rating. The instrument's job is to make the framework usable, defensible, and continuous — to turn legacy from a surprise into a managed trajectory.
A5: Workflow
B6: 1. On each Component sheet, complete the header block: component name, owner, assessor, date, mode, dependency classification, and trajectory.
B7: 2. Score each of the thirty-five tests against the anchored descriptors. Pick a score from the drop-down (1–5, or N/A where genuinely inapplicable). Record evidence status, the actual evidence cited, and the name of the person responsible for the cited evidence.
B8: 3. The workbook computes each heading rating using the gating rule, then the component rating from the worst heading.
B9: 4. On the System Dashboard, enter system-level details and add a row per component. The system rating is set by the worst rating among load-bearing components.
B10: 5. At the next assessment, copy the relevant Component sheet, complete a fresh scoring, and record the delta against the baseline. The score is the state. The delta is the signal.
A11: Calibration rules (from Section 3 of the framework)
B12: Demonstrated reality, not intent. The score reflects what is demonstrably true now, not what is planned. Evidence beats assertion — if it cannot be shown, it is not a 5.
B13: Score as-is, not as-designed. The cost of restoring optionality is the output of the assessment, not an input to the score.
B14: When uncertain, score down. A defensible amber is worth more than a flattering green. Optimism bias is the mechanism by which the decade-long surprise happens.
B15: Evidence absent ≠ score skipped. If evidence cannot be obtained, score the floor (1) and mark Evidence Status as Absent. The flag preserves the distinction; the score does not let the gap hide.
A16: Gating tests and heading rating
B17: Twelve of the thirty-five tests are designated gating tests (marked G in the Reference sheet). A score of 1 or 2 on any gating test floors the heading to RED regardless of the other tests. This implements the framework's load-bearing principle: the weakest load-bearing element governs.
B18: The non-gating tests give the heading its texture. The numeric thresholds used in this workbook are: average ≥ 4.0 = GREEN, 2.5 – 3.99 = AMBER, < 2.5 = RED. These thresholds are stated openly here so they can be challenged and adjusted; they sit on top of the categorical gating rule, which remains the spine.
A19: System-level roll-up
B20: The System Dashboard applies the worst-load-bearing-component rule. The system rating is set by the worst rating among components classified as Load-bearing. Contributing and Peripheral components are visible on the dashboard as context but do not set the system rating. This is a statement about reality, not a posture of pessimism: a system with a red load-bearing component has in fact lost the ability to evolve without first dealing with that component.
A21: Modes of assessment
B22: Full assessment runs all thirty-five tests, scheduled at design baseline, go-live, major architectural change, and at least annually for load-bearing components. The go-live score is the registered baseline and is non-optional.
B23: Light check runs the twelve gating tests only, fed wherever possible from telemetry. Quarterly, or continuously where instrumentation allows. Its job is to detect movement on the tests most likely to floor a heading and to trigger a full assessment. The light check is the smoke detector; the full assessment is the inspection.
A24: Known open areas (Section 9 of the framework)
B25: Numeric dependency weighting is deliberately not used as the spine. The categorical worst-load-bearing rule is what survives a hostile review. A weighting layer may be added later as a tiebreaker for ranking multiple red systems against finite remediation budget.
B26: Assessor competence is not defined by the framework. Consistency in this workbook depends on the anchored descriptors, the evidence indicators, and continuity of assessors across consecutive assessments of the same component.
A27: A note on neutrality
B28: The framework measures optionality. It does not road toward any product, supplier, or remediation approach. A green score does not imply migration. A red score does not prescribe a supplier. The rating is only worth defending if the framework was capable of returning the answer no one wanted.

Sheet System Dashboard
A1: System Dashboard
A3: System name | G3: System rating | I3: Set by
A4: Programme / department | G4: =IF(COUNTIFS(C15:C19,"Load-bearing",K15:K19,"RED")>0,"RED",IF(COUNTIFS(C15:C19,"Load-bearing",K15:K19,"AMBER")>0,"AMBER",IF(COUNTIFS(C15:C19,"Load-bearing",K15:K19,"GREEN")>0,"GREEN","—"))) -> — | I4: =IF(MAX(M15:M19)=0,"—",INDEX(A15:A19,MATCH(MAX(M15:M19),M15:M19,0))) -> —
A5: Senior Responsible Owner
A6: Lead assessor
A7: Assessment cycle
A8: Mode
A9: Date of this dashboard
A10: Previous dashboard date
A11: Notes
A13: Component register
A14: Component name | B14: Sheet reference | C14: Dependency class | D14: Portability | E14: Modularity | F14: Integration | G14: Modernisation | H14: Embedded IP | I14: Knowledge | J14: Observability | K14: Component rating | M14: Severity
A15: ='Component 1'!B3 -> 0 | B15: Component 1 | C15: ='Component 1'!B9 -> 0 | D15: ='Component 1'!J6 -> — | E15: ='Component 1'!J7 -> — | F15: ='Component 1'!J8 -> — | G15: ='Component 1'!J9 -> — | H15: ='Component 1'!J10 -> — | I15: ='Component 1'!J11 -> — | J15: ='Component 1'!J12 -> — | K15: ='Component 1'!H3 -> — | M15: =IF(C15="Load-bearing",IF(K15="RED",10,IF(K15="AMBER",5,IF(K15="GREEN",1,0))),0) -> 0
A16: ='Component 2'!B3 -> 0 | B16: Component 2 | C16: ='Component 2'!B9 -> 0 | D16: ='Component 2'!J6 -> — | E16: ='Component 2'!J7 -> — | F16: ='Component 2'!J8 -> — | G16: ='Component 2'!J9 -> — | H16: ='Component 2'!J10 -> — | I16: ='Component 2'!J11 -> — | J16: ='Component 2'!J12 -> — | K16: ='Component 2'!H3 -> — | M16: =IF(C16="Load-bearing",IF(K16="RED",10,IF(K16="AMBER",5,IF(K16="GREEN",1,0))),0) -> 0
A17: ='Component 3'!B3 -> 0 | B17: Component 3 | C17: ='Component 3'!B9 -> 0 | D17: ='Component 3'!J6 -> — | E17: ='Component 3'!J7 -> — | F17: ='Component 3'!J8 -> — | G17: ='Component 3'!J9 -> — | H17: ='Component 3'!J10 -> — | I17: ='Component 3'!J11 -> — | J17: ='Component 3'!J12 -> — | K17: ='Component 3'!H3 -> — | M17: =IF(C17="Load-bearing",IF(K17="RED",10,IF(K17="AMBER",5,IF(K17="GREEN",1,0))),0) -> 0
A18: ='Component 4'!B3 -> 0 | B18: Component 4 | C18: ='Component 4'!B9 -> 0 | D18: ='Component 4'!J6 -> — | E18: ='Component 4'!J7 -> — | F18: ='Component 4'!J8 -> — | G18: ='Component 4'!J9 -> — | H18: ='Component 4'!J10 -> — | I18: ='Component 4'!J11 -> — | J18: ='Component 4'!J12 -> — | K18: ='Component 4'!H3 -> — | M18: =IF(C18="Load-bearing",IF(K18="RED",10,IF(K18="AMBER",5,IF(K18="GREEN",1,0))),0) -> 0
A19: ='Component 5'!B3 -> 0 | B19: Component 5 | C19: ='Component 5'!B9 -> 0 | D19: ='Component 5'!J6 -> — | E19: ='Component 5'!J7 -> — | F19: ='Component 5'!J8 -> — | G19: ='Component 5'!J9 -> — | H19: ='Component 5'!J10 -> — | I19: ='Component 5'!J11 -> — | J19: ='Component 5'!J12 -> — | K19: ='Component 5'!H3 -> — | M19: =IF(C19="Load-bearing",IF(K19="RED",10,IF(K19="AMBER",5,IF(K19="GREEN",1,0))),0) -> 0
A21: Roll-up rule
A22: The system rating is set by the worst rating among components classified as Load-bearing. Contributing and Peripheral components are visible above as context but do not set the system rating. This is a statement about reality, not a posture of pessimism: a system with a red load-bearing component has in fact lost the ability to evolve without first dealing with that component. The framework's load-bearing principle is one rule applied at two levels — gating tests govern the heading the way load-bearing components govern the system.

Sheet Component 1
A1: Component Assessment — Component 1
A3: Component name | F3: Component rating | H3: =IF(COUNTIF(J6:J12,"RED")>0,"RED",IF(COUNTIF(J6:J12,"AMBER")>0,"AMBER",IF(COUNTIF(J6:J12,"GREEN")>0,"GREEN","—"))) -> —
A4: System / programme | F4: Lowest heading | H4: =IF(COUNTIF(J6:J12,"RED")>0,INDEX(F6:F12,MATCH("RED",J6:J12,0)),IF(COUNTIF(J6:J12,"AMBER")>0,INDEX(F6:F12,MATCH("AMBER",J6:J12,0)),IF(COUNTIF(J6:J12,"GREEN")>0,INDEX(F6:F12,MATCH("GREEN",J6:J12,0)),"—"))) -> —
A5: Owner (SRO or equivalent) | F5: Heading summary
A6: Assessor | F6: 1. Portability | I6: =IFERROR(ROUND(M15,2),"") | J6: =O15 -> —
A7: Assessment date | F7: 2. Modularity | I7: =IFERROR(ROUND(M16,2),"") | J7: =O16 -> —
A8: Mode | F8: 3. Integration | I8: =IFERROR(ROUND(M17,2),"") | J8: =O17 -> —
A9: Dependency classification | F9: 4. Modernisation | I9: =IFERROR(ROUND(M18,2),"") | J9: =O18 -> —
A10: Trajectory state | F10: 5. Embedded IP | I10: =IFERROR(ROUND(M19,2),"") | J10: =O19 -> —
A11: Previous assessment date | F11: 6. Knowledge Transferability | I11: =IFERROR(ROUND(M20,2),"") | J11: =O20 -> —
A12: Notes / context | F12: 7. Observability & Testability | I12: =IFERROR(ROUND(M21,2),"") | J12: =O21 -> —
A14: Test | B14: Test title | C14: G | D14: Score | E14: Anchor 1 | F14: Anchor 3 | G14: Anchor 5 | H14: Evidence status | I14: Evidence cited (what & where) | J14: Evidence owner | L14: HID | M14: Avg (non-gate) | N14: Min gate | O14: Rating
A15: 1. Portability — Can it be moved? | L15: 1 | M15: =IF(SUMPRODUCT((C16:C20<>"G")*ISNUMBER(D16:D20))=0,"",SUMPRODUCT((C16:C20<>"G")*ISNUMBER(D16:D20)*D16:D20)/SUMPRODUCT((C16:C20<>"G")*ISNUMBER(D16:D20))) | N15: =IF(MIN(IF(ISNUMBER(D16),D16,999))=999,"",MIN(IF(ISNUMBER(D16),D16,999))) | O15: =IF(M15="","—",IF(AND(ISNUMBER(N15),N15<=2),"RED",IF(M15>=4,"GREEN",IF(M15>=2.5,"AMBER","RED")))) -> —
A16: 1.1 | B16: Run on other infrastructure without redesign | C16: G | E16: Bound to its current host; moving it means a redesign. | F16: Movable to similar infrastructure with significant rework or constraints. | G16: Runs on alternative infrastructure with configuration changes only. | L16: 2 | M16: =IF(SUMPRODUCT((C22:C26<>"G")*ISNUMBER(D22:D26))=0,"",SUMPRODUCT((C22:C26<>"G")*ISNUMBER(D22:D26)*D22:D26)/SUMPRODUCT((C22:C26<>"G")*ISNUMBER(D22:D26))) | N16: =IF(MIN(IF(ISNUMBER(D23),D23,999))=999,"",MIN(IF(ISNUMBER(D23),D23,999))) | O16: =IF(M16="","—",IF(AND(ISNUMBER(N16),N16<=2),"RED",IF(M16>=4,"GREEN",IF(M16>=2.5,"AMBER","RED")))) -> —
A17: 1.2 | B17: Runtime dependencies current and supported | E17: Depends on out-of-support or end-of-life components. | F17: Mostly supported; some components near end-of-life or on extended support. | G17: All runtime dependencies are current and within their support lifecycle. | L17: 3 | M17: =IF(SUMPRODUCT((C28:C32<>"G")*ISNUMBER(D28:D32))=0,"",SUMPRODUCT((C28:C32<>"G")*ISNUMBER(D28:D32)*D28:D32)/SUMPRODUCT((C28:C32<>"G")*ISNUMBER(D28:D32))) | N17: =IF(MIN(IF(ISNUMBER(D30),D30,999))=999,"",MIN(IF(ISNUMBER(D30),D30,999))) | O17: =IF(M17="","—",IF(AND(ISNUMBER(N17),N17<=2),"RED",IF(M17>=4,"GREEN",IF(M17>=2.5,"AMBER","RED")))) -> —
A18: 1.3 | B18: Free of hard coupling to proprietary services or hardware | E18: Core function depends on proprietary services with no equivalent elsewhere. | F18: Uses proprietary services, but behind abstractions or with known alternatives. | G18: Uses portable, substitutable, or open interfaces throughout. | L18: 4 | M18: =IF(SUMPRODUCT((C34:C38<>"G")*ISNUMBER(D34:D38))=0,"",SUMPRODUCT((C34:C38<>"G")*ISNUMBER(D34:D38)*D34:D38)/SUMPRODUCT((C34:C38<>"G")*ISNUMBER(D34:D38))) | N18: =IF(MIN(IF(ISNUMBER(D34),D34,999))=999,"",MIN(IF(ISNUMBER(D34),D34,999))) | O18: =IF(M18="","—",IF(AND(ISNUMBER(N18),N18<=2),"RED",IF(M18>=4,"GREEN",IF(M18>=2.5,"AMBER","RED")))) -> —
A19: 1.4 | B19: Can be stood up from definition, not hand-built | E19: Environment exists only as a hand-built artefact; recreating it is reverse-engineering. | F19: Partially defined as code; some manual steps or tribal knowledge required. | G19: Fully reproducible from version-controlled definition. | L19: 5 | M19: =IF(SUMPRODUCT((C40:C44<>"G")*ISNUMBER(D40:D44))=0,"",SUMPRODUCT((C40:C44<>"G")*ISNUMBER(D40:D44)*D40:D44)/SUMPRODUCT((C40:C44<>"G")*ISNUMBER(D40:D44))) | N19: =IF(MIN(IF(ISNUMBER(D40),D40,999))=999,"",MIN(IF(ISNUMBER(D40),D40,999))) | O19: =IF(M19="","—",IF(AND(ISNUMBER(N19),N19<=2),"RED",IF(M19>=4,"GREEN",IF(M19>=2.5,"AMBER","RED")))) -> —
A20: 1.5 | B20: Data extractable and migratable without bespoke tooling | E20: Data is locked in a proprietary or undocumented store; extraction needs custom development. | F20: Extractable, but with effort, format conversion, or partial bespoke tooling. | G20: Stored in documented, standard formats; extractable with standard tools. | L20: 6 | M20: =IF(SUMPRODUCT((C46:C50<>"G")*ISNUMBER(D46:D50))=0,"",SUMPRODUCT((C46:C50<>"G")*ISNUMBER(D46:D50)*D46:D50)/SUMPRODUCT((C46:C50<>"G")*ISNUMBER(D46:D50))) | N20: =IF(MIN(IF(ISNUMBER(D46),D46,999))=999,"",MIN(IF(ISNUMBER(D46),D46,999))) | O20: =IF(M20="","—",IF(AND(ISNUMBER(N20),N20<=2),"RED",IF(M20>=4,"GREEN",IF(M20>=2.5,"AMBER","RED")))) -> —
A21: 2. Modularity — Can one part change without forcing the rest to change? | L21: 7 | M21: =IF(SUMPRODUCT((C52:C56<>"G")*ISNUMBER(D52:D56))=0,"",SUMPRODUCT((C52:C56<>"G")*ISNUMBER(D52:D56)*D52:D56)/SUMPRODUCT((C52:C56<>"G")*ISNUMBER(D52:D56))) | N21: =IF(MIN(IF(ISNUMBER(D52),D52,999),IF(ISNUMBER(D56),D56,999))=999,"",MIN(IF(ISNUMBER(D52),D52,999),IF(ISNUMBER(D56),D56,999))) | O21: =IF(M21="","—",IF(AND(ISNUMBER(N21),N21<=2),"RED",IF(M21>=4,"GREEN",IF(M21>=2.5,"AMBER","RED")))) -> —
A22: 2.1 | B22: Clearly bounded responsibilities | E22: Responsibilities are diffuse; no clear statement of what it does and does not own. | F22: Broadly bounded, but with overlaps or grey areas with other components. | G22: Clear, documented, single area of responsibility.
A23: 2.2 | B23: Can be developed, built and released independently | C23: G | E23: Cannot be built or released except as part of a larger coordinated effort. | F23: Independently buildable, but release is coupled to others in practice. | G23: Developed, built and released on its own cadence.
A24: 2.3 | B24: Internal parts separable, not rippling unpredictably | E24: Internally entangled; any change risks unpredictable effects elsewhere. | F24: Some internal structure; ripple is bounded but not fully predictable. | G24: Cleanly partitioned internally; change effects are localised and predictable.
A25: 2.4 | B25: Shared mutable state avoided or tightly controlled | E25: Shares mutable state freely; other components reach into its internals or vice versa. | F25: Some shared state, but mediated or documented. | G25: No uncontrolled shared state; interaction is through defined boundaries only.
A26: 2.5 | B26: A part can be replaced behind the same boundary | E26: Implementation and interface are inseparable; replacing the part means rebuilding the boundary. | F26: Replaceable with effort; the boundary leaks implementation detail. | G26: Parts sit behind stable boundaries and can be swapped freely.
A27: 3. Integration — Can its connections be changed plug-and-play?
A28: 3.1 | B28: Integrates through defined, documented interfaces | E28: Integrations rely on undocumented assumptions about behaviour, format, or timing. | F28: Interfaces exist and are partly documented; some assumptions remain implicit. | G28: All integrations through defined, documented interfaces.
A29: 3.2 | B29: Interfaces versioned so each side can change independently | E29: No versioning; any interface change is a breaking change. | F29: Some versioning or backward-compatibility discipline, inconsistently applied. | G29: Interfaces are versioned; producers and consumers can evolve independently.
A30: 3.3 | B30: An integration can be re-pointed without modifying the core | C30: G | E30: Integration endpoints are wired into the core; changing one means changing the component. | F30: Re-pointable with configuration change plus some code change. | G30: Integrations are externally configured; swappable without touching the core.
A31: 3.4 | B31: Free of brittle point-to-point couplings | E31: Depends on undocumented timing, ordering, or sequence to function. | F31: Some fragile couplings, known and worked around. | G31: No reliance on incidental timing or order; couplings are explicit and robust.
A32: 3.5 | B32: Integration contracts testable independently | E32: Integrations can only be tested against live counterpart systems. | F32: Partially testable in isolation; some paths need the real counterpart. | G32: Contracts can be fully exercised with stubs, mocks, or simulators.
A33: 4. Modernisation — Can the language and code be brought forward?
A34: 4.1 | B34: Language/framework supported and hireable for | C34: G | E34: Language/framework is obsolete; hiring or retaining skills is a known problem. | F34: Supported but ageing; skills pool is shrinking or expensive. | G34: Current, actively supported, and readily hireable for.
A35: 4.2 | B35: Codebase structured so change is safe, not feared | E35: Change is feared; the team avoids touching it where possible. | F35: Change is possible but slow and carries known risk. | G35: Change is routine and made with confidence.
A36: 4.3 | B36: Toolchain can still pull current, patched components | E36: Toolchain is frozen; pulling current or patched dependencies is impossible or breaks the build. | F36: Toolchain works but is dated; updates are difficult. | G36: Toolchain is current and pulls patched dependencies cleanly.
A37: 4.4 | B37: Free of dead, unexplained code no one dares remove | E37: Significant dead or unexplained code that no one will remove. | F37: Some dead or unclear code, identified but not cleared. | G37: Codebase is clean; no significant dead or unexplained sections.
A38: 4.5 | B38: A section could be rewritten without reverse-engineering it | E38: Rewriting any section first requires reverse-engineering what it does. | F38: Rewritable from a mix of documentation and code reading. | G38: Behaviour is specified well enough to rewrite directly.
A39: 5. Embedded IP — Is critical bespoke logic buried and unextractable?
A40: 5.1 | B40: Bespoke logic documented to the standard of its complexity | C40: G | E40: Critical bespoke logic is undocumented; it exists only as code. | F40: Partially documented; documentation lags the code or covers only the simple parts. | G40: Documented proportionate to its complexity and kept current.
A41: 5.2 | B41: Logic isolated and identifiable, not smeared through general code | E41: Bespoke logic is smeared through the codebase; you cannot point to where it lives. | F41: Mostly identifiable, with some logic embedded in general-purpose code. | G41: Isolated, identifiable, and clearly delineated from general-purpose code.
A42: 5.3 | B42: The IP could be re-implemented from its specification | E42: No specification exists; the code is the only statement of the IP. | F42: A specification exists but is incomplete or partly out of date. | G42: A complete, current specification exists independent of the code.
...

Sheet Component 2
A1: Component Assessment — Component 2
A3: Component name | F3: Component rating | H3: =IF(COUNTIF(J6:J12,"RED")>0,"RED",IF(COUNTIF(J6:J12,"AMBER")>0,"AMBER",IF(COUNTIF(J6:J12,"GREEN")>0,"GREEN","—"))) -> —
A4: System / programme | F4: Lowest heading | H4: =IF(COUNTIF(J6:J12,"RED")>0,INDEX(F6:F12,MATCH("RED",J6:J12,0)),IF(COUNTIF(J6:J12,"AMBER")>0,INDEX(F6:F12,MATCH("AMBER",J6:J12,0)),IF(COUNTIF(J6:J12,"GREEN")>0,INDEX(F6:F12,MATCH("GREEN",J6:J12,0)),"—"))) -> —
A5: Owner (SRO or equivalent) | F5: Heading summary
A6: Assessor | F6: 1. Portability | I6: =IFERROR(ROUND(M15,2),"") | J6: =O15 -> —
A7: Assessment date | F7: 2. Modularity | I7: =IFERROR(ROUND(M16,2),"") | J7: =O16 -> —
A8: Mode | F8: 3. Integration | I8: =IFERROR(ROUND(M17,2),"") | J8: =O17 -> —
A9: Dependency classification | F9: 4. Modernisation | I9: =IFERROR(ROUND(M18,2),"") | J9: =O18 -> —
A10: Trajectory state | F10: 5. Embedded IP | I10: =IFERROR(ROUND(M19,2),"") | J10: =O19 -> —
A11: Previous assessment date | F11: 6. Knowledge Transferability | I11: =IFERROR(ROUND(M20,2),"") | J11: =O20 -> —
A12: Notes / context | F12: 7. Observability & Testability | I12: =IFERROR(ROUND(M21,2),"") | J12: =O21 -> —
A14: Test | B14: Test title | C14: G | D14: Score | E14: Anchor 1 | F14: Anchor 3 | G14: Anchor 5 | H14: Evidence status | I14: Evidence cited (what & where) | J14: Evidence owner | L14: HID | M14: Avg (non-gate) | N14: Min gate | O14: Rating
A15: 1. Portability — Can it be moved? | L15: 1 | M15: =IF(SUMPRODUCT((C16:C20<>"G")*ISNUMBER(D16:D20))=0,"",SUMPRODUCT((C16:C20<>"G")*ISNUMBER(D16:D20)*D16:D20)/SUMPRODUCT((C16:C20<>"G")*ISNUMBER(D16:D20))) | N15: =IF(MIN(IF(ISNUMBER(D16),D16,999))=999,"",MIN(IF(ISNUMBER(D16),D16,999))) | O15: =IF(M15="","—",IF(AND(ISNUMBER(N15),N15<=2),"RED",IF(M15>=4,"GREEN",IF(M15>=2.5,"AMBER","RED")))) -> —
A16: 1.1 | B16: Run on other infrastructure without redesign | C16: G | E16: Bound to its current host; moving it means a redesign. | F16: Movable to similar infrastructure with significant rework or constraints. | G16: Runs on alternative infrastructure with configuration changes only. | L16: 2 | M16: =IF(SUMPRODUCT((C22:C26<>"G")*ISNUMBER(D22:D26))=0,"",SUMPRODUCT((C22:C26<>"G")*ISNUMBER(D22:D26)*D22:D26)/SUMPRODUCT((C22:C26<>"G")*ISNUMBER(D22:D26))) | N16: =IF(MIN(IF(ISNUMBER(D23),D23,999))=999,"",MIN(IF(ISNUMBER(D23),D23,999))) | O16: =IF(M16="","—",IF(AND(ISNUMBER(N16),N16<=2),"RED",IF(M16>=4,"GREEN",IF(M16>=2.5,"AMBER","RED")))) -> —
A17: 1.2 | B17: Runtime dependencies current and supported | E17: Depends on out-of-support or end-of-life components. | F17: Mostly supported; some components near end-of-life or on extended support. | G17: All runtime dependencies are current and within their support lifecycle. | L17: 3 | M17: =IF(SUMPRODUCT((C28:C32<>"G")*ISNUMBER(D28:D32))=0,"",SUMPRODUCT((C28:C32<>"G")*ISNUMBER(D28:D32)*D28:D32)/SUMPRODUCT((C28:C32<>"G")*ISNUMBER(D28:D32))) | N17: =IF(MIN(IF(ISNUMBER(D30),D30,999))=999,"",MIN(IF(ISNUMBER(D30),D30,999))) | O17: =IF(M17="","—",IF(AND(ISNUMBER(N17),N17<=2),"RED",IF(M17>=4,"GREEN",IF(M17>=2.5,"AMBER","RED")))) -> —
A18: 1.3 | B18: Free of hard coupling to proprietary services or hardware | E18: Core function depends on proprietary services with no equivalent elsewhere. | F18: Uses proprietary services, but behind abstractions or with known alternatives. | G18: Uses portable, substitutable, or open interfaces throughout. | L18: 4 | M18: =IF(SUMPRODUCT((C34:C38<>"G")*ISNUMBER(D34:D38))=0,"",SUMPRODUCT((C34:C38<>"G")*ISNUMBER(D34:D38)*D34:D38)/SUMPRODUCT((C34:C38<>"G")*ISNUMBER(D34:D38))) | N18: =IF(MIN(IF(ISNUMBER(D34),D34,999))=999,"",MIN(IF(ISNUMBER(D34),D34,999))) | O18: =IF(M18="","—",IF(AND(ISNUMBER(N18),N18<=2),"RED",IF(M18>=4,"GREEN",IF(M18>=2.5,"AMBER","RED")))) -> —
A19: 1.4 | B19: Can be stood up from definition, not hand-built | E19: Environment exists only as a hand-built artefact; recreating it is reverse-engineering. | F19: Partially defined as code; some manual steps or tribal knowledge required. | G19: Fully reproducible from version-controlled definition. | L19: 5 | M19: =IF(SUMPRODUCT((C40:C44<>"G")*ISNUMBER(D40:D44))=0,"",SUMPRODUCT((C40:C44<>"G")*ISNUMBER(D40:D44)*D40:D44)/SUMPRODUCT((C40:C44<>"G")*ISNUMBER(D40:D44))) | N19: =IF(MIN(IF(ISNUMBER(D40),D40,999))=999,"",MIN(IF(ISNUMBER(D40),D40,999))) | O19: =IF(M19="","—",IF(AND(ISNUMBER(N19),N19<=2),"RED",IF(M19>=4,"GREEN",IF(M19>=2.5,"AMBER","RED")))) -> —
A20: 1.5 | B20: Data extractable and migratable without bespoke tooling | E20: Data is locked in a proprietary or undocumented store; extraction needs custom development. | F20: Extractable, but with effort, format conversion, or partial bespoke tooling. | G20: Stored in documented, standard formats; extractable with standard tools. | L20: 6 | M20: =IF(SUMPRODUCT((C46:C50<>"G")*ISNUMBER(D46:D50))=0,"",SUMPRODUCT((C46:C50<>"G")*ISNUMBER(D46:D50)*D46:D50)/SUMPRODUCT((C46:C50<>"G")*ISNUMBER(D46:D50))) | N20: =IF(MIN(IF(ISNUMBER(D46),D46,999))=999,"",MIN(IF(ISNUMBER(D46),D46,999))) | O20: =IF(M20="","—",IF(AND(ISNUMBER(N20),N20<=2),"RED",IF(M20>=4,"GREEN",IF(M20>=2.5,"AMBER","RED")))) -> —
A21: 2. Modularity — Can one part change without forcing the rest to change? | L21: 7 | M21: =IF(SUMPRODUCT((C52:C56<>"G")*ISNUMBER(D52:D56))=0,"",SUMPRODUCT((C52:C56<>"G")*ISNUMBER(D52:D56)*D52:D56)/SUMPRODUCT((C52:C56<>"G")*ISNUMBER(D52:D56))) | N21: =IF(MIN(IF(ISNUMBER(D52),D52,999),IF(ISNUMBER(D56),D56,999))=999,"",MIN(IF(ISNUMBER(D52),D52,999),IF(ISNUMBER(D56),D56,999))) | O21: =IF(M21="","—",IF(AND(ISNUMBER(N21),N21<=2),"RED",IF(M21>=4,"GREEN",IF(M21>=2.5,"AMBER","RED")))) -> —
A22: 2.1 | B22: Clearly bounded responsibilities | E22: Responsibilities are diffuse; no clear statement of what it does and does not own. | F22: Broadly bounded, but with overlaps or grey areas with other components. | G22: Clear, documented, single area of responsibility.
A23: 2.2 | B23: Can be developed, built and released independently | C23: G | E23: Cannot be built or released except as part of a larger coordinated effort. | F23: Independently buildable, but release is coupled to others in practice. | G23: Developed, built and released on its own cadence.
A24: 2.3 | B24: Internal parts separable, not rippling unpredictably | E24: Internally entangled; any change risks unpredictable effects elsewhere. | F24: Some internal structure; ripple is bounded but not fully predictable. | G24: Cleanly partitioned internally; change effects are localised and predictable.
A25: 2.4 | B25: Shared mutable state avoided or tightly controlled | E25: Shares mutable state freely; other components reach into its internals or vice versa. | F25: Some shared state, but mediated or documented. | G25: No uncontrolled shared state; interaction is through defined boundaries only.
A26: 2.5 | B26: A part can be replaced behind the same boundary | E26: Implementation and interface are inseparable; replacing the part means rebuilding the boundary. | F26: Replaceable with effort; the boundary leaks implementation detail. | G26: Parts sit behind stable boundaries and can be swapped freely.
A27: 3. Integration — Can its connections be changed plug-and-play?
A28: 3.1 | B28: Integrates through defined, documented interfaces | E28: Integrations rely on undocumented assumptions about behaviour, format, or timing. | F28: Interfaces exist and are partly documented; some assumptions remain implicit. | G28: All integrations through defined, documented interfaces.
A29: 3.2 | B29: Interfaces versioned so each side can change independently | E29: No versioning; any interface change is a breaking change. | F29: Some versioning or backward-compatibility discipline, inconsistently applied. | G29: Interfaces are versioned; producers and consumers can evolve independently.
A30: 3.3 | B30: An integration can be re-pointed without modifying the core | C30: G | E30: Integration endpoints are wired into the core; changing one means changing the component. | F30: Re-pointable with configuration change plus some code change. | G30: Integrations are externally configured; swappable without touching the core.
A31: 3.4 | B31: Free of brittle point-to-point couplings | E31: Depends on undocumented timing, ordering, or sequence to function. | F31: Some fragile couplings, known and worked around. | G31: No reliance on incidental timing or order; couplings are explicit and robust.
A32: 3.5 | B32: Integration contracts testable independently | E32: Integrations can only be tested against live counterpart systems. | F32: Partially testable in isolation; some paths need the real counterpart. | G32: Contracts can be fully exercised with stubs, mocks, or simulators.
A33: 4. Modernisation — Can the language and code be brought forward?
A34: 4.1 | B34: Language/framework supported and hireable for | C34: G | E34: Language/framework is obsolete; hiring or retaining skills is a known problem. | F34: Supported but ageing; skills pool is shrinking or expensive. | G34: Current, actively supported, and readily hireable for.
A35: 4.2 | B35: Codebase structured so change is safe, not feared | E35: Change is feared; the team avoids touching it where possible. | F35: Change is possible but slow and carries known risk. | G35: Change is routine and made with confidence.
A36: 4.3 | B36: Toolchain can still pull current, patched components | E36: Toolchain is frozen; pulling current or patched dependencies is impossible or breaks the build. | F36: Toolchain works but is dated; updates are difficult. | G36: Toolchain is current and pulls patched dependencies cleanly.
A37: 4.4 | B37: Free of dead, unexplained code no one dares remove | E37: Significant dead or unexplained code that no one will remove. | F37: Some dead or unclear code, identified but not cleared. | G37: Codebase is clean; no significant dead or unexplained sections.
A38: 4.5 | B38: A section could be rewritten without reverse-engineering it | E38: Rewriting any section first requires reverse-engineering what it does. | F38: Rewritable from a mix of documentation and code reading. | G38: Behaviour is specified well enough to rewrite directly.
A39: 5. Embedded IP — Is critical bespoke logic buried and unextractable?
A40: 5.1 | B40: Bespoke logic documented to the standard of its complexity | C40: G | E40: Critical bespoke logic is undocumented; it exists only as code. | F40: Partially documented; documentation lags the code or covers only the simple parts. | G40: Documented proportionate to its complexity and kept current.
A41: 5.2 | B41: Logic isolated and identifiable, not smeared through general code | E41: Bespoke logic is smeared through the codebase; you cannot point to where it lives. | F41: Mostly identifiable, with some logic embedded in general-purpose code. | G41: Isolated, identifiable, and clearly delineated from general-purpose code.
A42: 5.3 | B42: The IP could be re-implemented from its specification | E42: No specification exists; the code is the only statement of the IP. | F42: A specification exists but is incomplete or partly out of date. | G42: A complete, current specification exists independent of the code.
...

Sheet Component 3
A1: Component Assessment — Component 3
A3: Component name | F3: Component rating | H3: =IF(COUNTIF(J6:J12,"RED")>0,"RED",IF(COUNTIF(J6:J12,"AMBER")>0,"AMBER",IF(COUNTIF(J6:J12,"GREEN")>0,"GREEN","—"))) -> —
A4: System / programme | F4: Lowest heading | H4: =IF(COUNTIF(J6:J12,"RED")>0,INDEX(F6:F12,MATCH("RED",J6:J12,0)),IF(COUNTIF(J6:J12,"AMBER")>0,INDEX(F6:F12,MATCH("AMBER",J6:J12,0)),IF(COUNTIF(J6:J12,"GREEN")>0,INDEX(F6:F12,MATCH("GREEN",J6:J12,0)),"—"))) -> —
A5: Owner (SRO or equivalent) | F5: Heading summary
A6: Assessor | F6: 1. Portability | I6: =IFERROR(ROUND(M15,2),"") | J6: =O15 -> —
A7: Assessment date | F7: 2. Modularity | I7: =IFERROR(ROUND(M16,2),"") | J7: =O16 -> —
A8: Mode | F8: 3. Integration | I8: =IFERROR(ROUND(M17,2),"") | J8: =O17 -> —
A9: Dependency classification | F9: 4. Modernisation | I9: =IFERROR(ROUND(M18,2),"") | J9: =O18 -> —
A10: Trajectory state | F10: 5. Embedded IP | I10: =IFERROR(ROUND(M19,2),"") | J10: =O19 -> —
A11: Previous assessment date | F11: 6. Knowledge Transferability | I11: =IFERROR(ROUND(M20,2),"") | J11: =O20 -> —
A12: Notes / context | F12: 7. Observability & Testability | I12: =IFERROR(ROUND(M21,2),"") | J12: =O21 -> —
A14: Test | B14: Test title | C14: G | D14: Score | E14: Anchor 1 | F14: Anchor 3 | G14: Anchor 5 | H14: Evidence status | I14: Evidence cited (what & where) | J14: Evidence owner | L14: HID | M14: Avg (non-gate) | N14: Min gate | O14: Rating
A15: 1. Portability — Can it be moved? | L15: 1 | M15: =IF(SUMPRODUCT((C16:C20<>"G")*ISNUMBER(D16:D20))=0,"",SUMPRODUCT((C16:C20<>"G")*ISNUMBER(D16:D20)*D16:D20)/SUMPRODUCT((C16:C20<>"G")*ISNUMBER(D16:D20))) | N15: =IF(MIN(IF(ISNUMBER(D16),D16,999))=999,"",MIN(IF(ISNUMBER(D16),D16,999))) | O15: =IF(M15="","—",IF(AND(ISNUMBER(N15),N15<=2),"RED",IF(M15>=4,"GREEN",IF(M15>=2.5,"AMBER","RED")))) -> —
A16: 1.1 | B16: Run on other infrastructure without redesign | C16: G | E16: Bound to its current host; moving it means a redesign. | F16: Movable to similar infrastructure with significant rework or constraints. | G16: Runs on alternative infrastructure with configuration changes only. | L16: 2 | M16: =IF(SUMPRODUCT((C22:C26<>"G")*ISNUMBER(D22:D26))=0,"",SUMPRODUCT((C22:C26<>"G")*ISNUMBER(D22:D26)*D22:D26)/SUMPRODUCT((C22:C26<>"G")*ISNUMBER(D22:D26))) | N16: =IF(MIN(IF(ISNUMBER(D23),D23,999))=999,"",MIN(IF(ISNUMBER(D23),D23,999))) | O16: =IF(M16="","—",IF(AND(ISNUMBER(N16),N16<=2),"RED",IF(M16>=4,"GREEN",IF(M16>=2.5,"AMBER","RED")))) -> —
A17: 1.2 | B17: Runtime dependencies current and supported | E17: Depends on out-of-support or end-of-life components. | F17: Mostly supported; some components near end-of-life or on extended support. | G17: All runtime dependencies are current and within their support lifecycle. | L17: 3 | M17: =IF(SUMPRODUCT((C28:C32<>"G")*ISNUMBER(D28:D32))=0,"",SUMPRODUCT((C28:C32<>"G")*ISNUMBER(D28:D32)*D28:D32)/SUMPRODUCT((C28:C32<>"G")*ISNUMBER(D28:D32))) | N17: =IF(MIN(IF(ISNUMBER(D30),D30,999))=999,"",MIN(IF(ISNUMBER(D30),D30,999))) | O17: =IF(M17="","—",IF(AND(ISNUMBER(N17),N17<=2),"RED",IF(M17>=4,"GREEN",IF(M17>=2.5,"AMBER","RED")))) -> —
A18: 1.3 | B18: Free of hard coupling to proprietary services or hardware | E18: Core function depends on proprietary services with no equivalent elsewhere. | F18: Uses proprietary services, but behind abstractions or with known alternatives. | G18: Uses portable, substitutable, or open interfaces throughout. | L18: 4 | M18: =IF(SUMPRODUCT((C34:C38<>"G")*ISNUMBER(D34:D38))=0,"",SUMPRODUCT((C34:C38<>"G")*ISNUMBER(D34:D38)*D34:D38)/SUMPRODUCT((C34:C38<>"G")*ISNUMBER(D34:D38))) | N18: =IF(MIN(IF(ISNUMBER(D34),D34,999))=999,"",MIN(IF(ISNUMBER(D34),D34,999))) | O18: =IF(M18="","—",IF(AND(ISNUMBER(N18),N18<=2),"RED",IF(M18>=4,"GREEN",IF(M18>=2.5,"AMBER","RED")))) -> —
A19: 1.4 | B19: Can be stood up from definition, not hand-built | E19: Environment exists only as a hand-built artefact; recreating it is reverse-engineering. | F19: Partially defined as code; some manual steps or tribal knowledge required. | G19: Fully reproducible from version-controlled definition. | L19: 5 | M19: =IF(SUMPRODUCT((C40:C44<>"G")*ISNUMBER(D40:D44))=0,"",SUMPRODUCT((C40:C44<>"G")*ISNUMBER(D40:D44)*D40:D44)/SUMPRODUCT((C40:C44<>"G")*ISNUMBER(D40:D44))) | N19: =IF(MIN(IF(ISNUMBER(D40),D40,999))=999,"",MIN(IF(ISNUMBER(D40),D40,999))) | O19: =IF(M19="","—",IF(AND(ISNUMBER(N19),N19<=2),"RED",IF(M19>=4,"GREEN",IF(M19>=2.5,"AMBER","RED")))) -> —
A20: 1.5 | B20: Data extractable and migratable without bespoke tooling | E20: Data is locked in a proprietary or undocumented store; extraction needs custom development. | F20: Extractable, but with effort, format conversion, or partial bespoke tooling. | G20: Stored in documented, standard formats; extractable with standard tools. | L20: 6 | M20: =IF(SUMPRODUCT((C46:C50<>"G")*ISNUMBER(D46:D50))=0,"",SUMPRODUCT((C46:C50<>"G")*ISNUMBER(D46:D50)*D46:D50)/SUMPRODUCT((C46:C50<>"G")*ISNUMBER(D46:D50))) | N20: =IF(MIN(IF(ISNUMBER(D46),D46,999))=999,"",MIN(IF(ISNUMBER(D46),D46,999))) | O20: =IF(M20="","—",IF(AND(ISNUMBER(N20),N20<=2),"RED",IF(M20>=4,"GREEN",IF(M20>=2.5,"AMBER","RED")))) -> —
A21: 2. Modularity — Can one part change without forcing the rest to change? | L21: 7 | M21: =IF(SUMPRODUCT((C52:C56<>"G")*ISNUMBER(D52:D56))=0,"",SUMPRODUCT((C52:C56<>"G")*ISNUMBER(D52:D56)*D52:D56)/SUMPRODUCT((C52:C56<>"G")*ISNUMBER(D52:D56))) | N21: =IF(MIN(IF(ISNUMBER(D52),D52,999),IF(ISNUMBER(D56),D56,999))=999,"",MIN(IF(ISNUMBER(D52),D52,999),IF(ISNUMBER(D56),D56,999))) | O21: =IF(M21="","—",IF(AND(ISNUMBER(N21),N21<=2),"RED",IF(M21>=4,"GREEN",IF(M21>=2.5,"AMBER","RED")))) -> —
A22: 2.1 | B22: Clearly bounded responsibilities | E22: Responsibilities are diffuse; no clear statement of what it does and does not own. | F22: Broadly bounded, but with overlaps or grey areas with other components. | G22: Clear, documented, single area of responsibility.
A23: 2.2 | B23: Can be developed, built and released independently | C23: G | E23: Cannot be built or released except as part of a larger coordinated effort. | F23: Independently buildable, but release is coupled to others in practice. | G23: Developed, built and released on its own cadence.
A24: 2.3 | B24: Internal parts separable, not rippling unpredictably | E24: Internally entangled; any change risks unpredictable effects elsewhere. | F24: Some internal structure; ripple is bounded but not fully predictable. | G24: Cleanly partitioned internally; change effects are localised and predictable.
A25: 2.4 | B25: Shared mutable state avoided or tightly controlled | E25: Shares mutable state freely; other components reach into its internals or vice versa. | F25: Some shared state, but mediated or documented. | G25: No uncontrolled shared state; interaction is through defined boundaries only.
A26: 2.5 | B26: A part can be replaced behind the same boundary | E26: Implementation and interface are inseparable; replacing the part means rebuilding the boundary. | F26: Replaceable with effort; the boundary leaks implementation detail. | G26: Parts sit behind stable boundaries and can be swapped freely.
A27: 3. Integration — Can its connections be changed plug-and-play?
A28: 3.1 | B28: Integrates through defined, documented interfaces | E28: Integrations rely on undocumented assumptions about behaviour, format, or timing. | F28: Interfaces exist and are partly documented; some assumptions remain implicit. | G28: All integrations through defined, documented interfaces.
A29: 3.2 | B29: Interfaces versioned so each side can change independently | E29: No versioning; any interface change is a breaking change. | F29: Some versioning or backward-compatibility discipline, inconsistently applied. | G29: Interfaces are versioned; producers and consumers can evolve independently.
A30: 3.3 | B30: An integration can be re-pointed without modifying the core | C30: G | E30: Integration endpoints are wired into the core; changing one means changing the component. | F30: Re-pointable with configuration change plus some code change. | G30: Integrations are externally configured; swappable without touching the core.
A31: 3.4 | B31: Free of brittle point-to-point couplings | E31: Depends on undocumented timing, ordering, or sequence to function. | F31: Some fragile couplings, known and worked around. | G31: No reliance on incidental timing or order; couplings are explicit and robust.
A32: 3.5 | B32: Integration contracts testable independently | E32: Integrations can only be tested against live counterpart systems. | F32: Partially testable in isolation; some paths need the real counterpart. | G32: Contracts can be fully exercised with stubs, mocks, or simulators.
A33: 4. Modernisation — Can the language and code be brought forward?
A34: 4.1 | B34: Language/framework supported and hireable for | C34: G | E34: Language/framework is obsolete; hiring or retaining skills is a known problem. | F34: Supported but ageing; skills pool is shrinking or expensive. | G34: Current, actively supported, and readily hireable for.
A35: 4.2 | B35: Codebase structured so change is safe, not feared | E35: Change is feared; the team avoids touching it where possible. | F35: Change is possible but slow and carries known risk. | G35: Change is routine and made with confidence.
A36: 4.3 | B36: Toolchain can still pull current, patched components | E36: Toolchain is frozen; pulling current or patched dependencies is impossible or breaks the build. | F36: Toolchain works but is dated; updates are difficult. | G36: Toolchain is current and pulls patched dependencies cleanly.
A37: 4.4 | B37: Free of dead, unexplained code no one dares remove | E37: Significant dead or unexplained code that no one will remove. | F37: Some dead or unclear code, identified but not cleared. | G37: Codebase is clean; no significant dead or unexplained sections.
A38: 4.5 | B38: A section could be rewritten without reverse-engineering it | E38: Rewriting any section first requires reverse-engineering what it does. | F38: Rewritable from a mix of documentation and code reading. | G38: Behaviour is specified well enough to rewrite directly.
A39: 5. Embedded IP — Is critical bespoke logic buried and unextractable?
A40: 5.1 | B40: Bespoke logic documented to the standard of its complexity | C40: G | E40: Critical bespoke logic is undocumented; it exists only as code. | F40: Partially documented; documentation lags the code or covers only the simple parts. | G40: Documented proportionate to its complexity and kept current.
A41: 5.2 | B41: Logic isolated and identifiable, not smeared through general code | E41: Bespoke logic is smeared through the codebase; you cannot point to where it lives. | F41: Mostly identifiable, with some logic embedded in general-purpose code. | G41: Isolated, identifiable, and clearly delineated from general-purpose code.
A42: 5.3 | B42: The IP could be re-implemented from its specification | E42: No specification exists; the code is the only statement of the IP. | F42: A specification exists but is incomplete or partly out of date. | G42: A complete, current specification exists independent of the code.
...

Sheet Component 4
A1: Component Assessment — Component 4
A3: Component name | F3: Component rating | H3: =IF(COUNTIF(J6:J12,"RED")>0,"RED",IF(COUNTIF(J6:J12,"AMBER")>0,"AMBER",IF(COUNTIF(J6:J12,"GREEN")>0,"GREEN","—"))) -> —
A4: System / programme | F4: Lowest heading | H4: =IF(COUNTIF(J6:J12,"RED")>0,INDEX(F6:F12,MATCH("RED",J6:J12,0)),IF(COUNTIF(J6:J12,"AMBER")>0,INDEX(F6:F12,MATCH("AMBER",J6:J12,0)),IF(COUNTIF(J6:J12,"GREEN")>0,INDEX(F6:F12,MATCH("GREEN",J6:J12,0)),"—"))) -> —
A5: Owner (SRO or equivalent) | F5: Heading summary
A6: Assessor | F6: 1. Portability | I6: =IFERROR(ROUND(M15,2),"") | J6: =O15 -> —
A7: Assessment date | F7: 2. Modularity | I7: =IFERROR(ROUND(M16,2),"") | J7: =O16 -> —
A8: Mode | F8: 3. Integration | I8: =IFERROR(ROUND(M17,2),"") | J8: =O17 -> —
A9: Dependency classification | F9: 4. Modernisation | I9: =IFERROR(ROUND(M18,2),"") | J9: =O18 -> —
A10: Trajectory state | F10: 5. Embedded IP | I10: =IFERROR(ROUND(M19,2),"") | J10: =O19 -> —
A11: Previous assessment date | F11: 6. Knowledge Transferability | I11: =IFERROR(ROUND(M20,2),"") | J11: =O20 -> —
A12: Notes / context | F12: 7. Observability & Testability | I12: =IFERROR(ROUND(M21,2),"") | J12: =O21 -> —
A14: Test | B14: Test title | C14: G | D14: Score | E14: Anchor 1 | F14: Anchor 3 | G14: Anchor 5 | H14: Evidence status | I14: Evidence cited (what & where) | J14: Evidence owner | L14: HID | M14: Avg (non-gate) | N14: Min gate | O14: Rating
A15: 1. Portability — Can it be moved? | L15: 1 | M15: =IF(SUMPRODUCT((C16:C20<>"G")*ISNUMBER(D16:D20))=0,"",SUMPRODUCT((C16:C20<>"G")*ISNUMBER(D16:D20)*D16:D20)/SUMPRODUCT((C16:C20<>"G")*ISNUMBER(D16:D20))) | N15: =IF(MIN(IF(ISNUMBER(D16),D16,999))=999,"",MIN(IF(ISNUMBER(D16),D16,999))) | O15: =IF(M15="","—",IF(AND(ISNUMBER(N15),N15<=2),"RED",IF(M15>=4,"GREEN",IF(M15>=2.5,"AMBER","RED")))) -> —
A16: 1.1 | B16: Run on other infrastructure without redesign | C16: G | E16: Bound to its current host; moving it means a redesign. | F16: Movable to similar infrastructure with significant rework or constraints. | G16: Runs on alternative infrastructure with configuration changes only. | L16: 2 | M16: =IF(SUMPRODUCT((C22:C26<>"G")*ISNUMBER(D22:D26))=0,"",SUMPRODUCT((C22:C26<>"G")*ISNUMBER(D22:D26)*D22:D26)/SUMPRODUCT((C22:C26<>"G")*ISNUMBER(D22:D26))) | N16: =IF(MIN(IF(ISNUMBER(D23),D23,999))=999,"",MIN(IF(ISNUMBER(D23),D23,999))) | O16: =IF(M16="","—",IF(AND(ISNUMBER(N16),N16<=2),"RED",IF(M16>=4,"GREEN",IF(M16>=2.5,"AMBER","RED")))) -> —
A17: 1.2 | B17: Runtime dependencies current and supported | E17: Depends on out-of-support or end-of-life components. | F17: Mostly supported; some components near end-of-life or on extended support. | G17: All runtime dependencies are current and within their support lifecycle. | L17: 3 | M17: =IF(SUMPRODUCT((C28:C32<>"G")*ISNUMBER(D28:D32))=0,"",SUMPRODUCT((C28:C32<>"G")*ISNUMBER(D28:D32)*D28:D32)/SUMPRODUCT((C28:C32<>"G")*ISNUMBER(D28:D32))) | N17: =IF(MIN(IF(ISNUMBER(D30),D30,999))=999,"",MIN(IF(ISNUMBER(D30),D30,999))) | O17: =IF(M17="","—",IF(AND(ISNUMBER(N17),N17<=2),"RED",IF(M17>=4,"GREEN",IF(M17>=2.5,"AMBER","RED")))) -> —
A18: 1.3 | B18: Free of hard coupling to proprietary services or hardware | E18: Core function depends on proprietary services with no equivalent elsewhere. | F18: Uses proprietary services, but behind abstractions or with known alternatives. | G18: Uses portable, substitutable, or open interfaces throughout. | L18: 4 | M18: =IF(SUMPRODUCT((C34:C38<>"G")*ISNUMBER(D34:D38))=0,"",SUMPRODUCT((C34:C38<>"G")*ISNUMBER(D34:D38)*D34:D38)/SUMPRODUCT((C34:C38<>"G")*ISNUMBER(D34:D38))) | N18: =IF(MIN(IF(ISNUMBER(D34),D34,999))=999,"",MIN(IF(ISNUMBER(D34),D34,999))) | O18: =IF(M18="","—",IF(AND(ISNUMBER(N18),N18<=2),"RED",IF(M18>=4,"GREEN",IF(M18>=2.5,"AMBER","RED")))) -> —
A19: 1.4 | B19: Can be stood up from definition, not hand-built | E19: Environment exists only as a hand-built artefact; recreating it is reverse-engineering. | F19: Partially defined as code; some manual steps or tribal knowledge required. | G19: Fully reproducible from version-controlled definition. | L19: 5 | M19: =IF(SUMPRODUCT((C40:C44<>"G")*ISNUMBER(D40:D44))=0,"",SUMPRODUCT((C40:C44<>"G")*ISNUMBER(D40:D44)*D40:D44)/SUMPRODUCT((C40:C44<>"G")*ISNUMBER(D40:D44))) | N19: =IF(MIN(IF(ISNUMBER(D40),D40,999))=999,"",MIN(IF(ISNUMBER(D40),D40,999))) | O19: =IF(M19="","—",IF(AND(ISNUMBER(N19),N19<=2),"RED",IF(M19>=4,"GREEN",IF(M19>=2.5,"AMBER","RED")))) -> —
A20: 1.5 | B20: Data extractable and migratable without bespoke tooling | E20: Data is locked in a proprietary or undocumented store; extraction needs custom development. | F20: Extractable, but with effort, format conversion, or partial bespoke tooling. | G20: Stored in documented, standard formats; extractable with standard tools. | L20: 6 | M20: =IF(SUMPRODUCT((C46:C50<>"G")*ISNUMBER(D46:D50))=0,"",SUMPRODUCT((C46:C50<>"G")*ISNUMBER(D46:D50)*D46:D50)/SUMPRODUCT((C46:C50<>"G")*ISNUMBER(D46:D50))) | N20: =IF(MIN(IF(ISNUMBER(D46),D46,999))=999,"",MIN(IF(ISNUMBER(D46),D46,999))) | O20: =IF(M20="","—",IF(AND(ISNUMBER(N20),N20<=2),"RED",IF(M20>=4,"GREEN",IF(M20>=2.5,"AMBER","RED")))) -> —
A21: 2. Modularity — Can one part change without forcing the rest to change? | L21: 7 | M21: =IF(SUMPRODUCT((C52:C56<>"G")*ISNUMBER(D52:D56))=0,"",SUMPRODUCT((C52:C56<>"G")*ISNUMBER(D52:D56)*D52:D56)/SUMPRODUCT((C52:C56<>"G")*ISNUMBER(D52:D56))) | N21: =IF(MIN(IF(ISNUMBER(D52),D52,999),IF(ISNUMBER(D56),D56,999))=999,"",MIN(IF(ISNUMBER(D52),D52,999),IF(ISNUMBER(D56),D56,999))) | O21: =IF(M21="","—",IF(AND(ISNUMBER(N21),N21<=2),"RED",IF(M21>=4,"GREEN",IF(M21>=2.5,"AMBER","RED")))) -> —
A22: 2.1 | B22: Clearly bounded responsibilities | E22: Responsibilities are diffuse; no clear statement of what it does and does not own. | F22: Broadly bounded, but with overlaps or grey areas with other components. | G22: Clear, documented, single area of responsibility.
A23: 2.2 | B23: Can be developed, built and released independently | C23: G | E23: Cannot be built or released except as part of a larger coordinated effort. | F23: Independently buildable, but release is coupled to others in practice. | G23: Developed, built and released on its own cadence.
A24: 2.3 | B24: Internal parts separable, not rippling unpredictably | E24: Internally entangled; any change risks unpredictable effects elsewhere. | F24: Some internal structure; ripple is bounded but not fully predictable. | G24: Cleanly partitioned internally; change effects are localised and predictable.
A25: 2.4 | B25: Shared mutable state avoided or tightly controlled | E25: Shares mutable state freely; other components reach into its internals or vice versa. | F25: Some shared state, but mediated or documented. | G25: No uncontrolled shared state; interaction is through defined boundaries only.
A26: 2.5 | B26: A part can be replaced behind the same boundary | E26: Implementation and interface are inseparable; replacing the part means rebuilding the boundary. | F26: Replaceable with effort; the boundary leaks implementation detail. | G26: Parts sit behind stable boundaries and can be swapped freely.
A27: 3. Integration — Can its connections be changed plug-and-play?
A28: 3.1 | B28: Integrates through defined, documented interfaces | E28: Integrations rely on undocumented assumptions about behaviour, format, or timing. | F28: Interfaces exist and are partly documented; some assumptions remain implicit. | G28: All integrations through defined, documented interfaces.
A29: 3.2 | B29: Interfaces versioned so each side can change independently | E29: No versioning; any interface change is a breaking change. | F29: Some versioning or backward-compatibility discipline, inconsistently applied. | G29: Interfaces are versioned; producers and consumers can evolve independently.
A30: 3.3 | B30: An integration can be re-pointed without modifying the core | C30: G | E30: Integration endpoints are wired into the core; changing one means changing the component. | F30: Re-pointable with configuration change plus some code change. | G30: Integrations are externally configured; swappable without touching the core.
A31: 3.4 | B31: Free of brittle point-to-point couplings | E31: Depends on undocumented timing, ordering, or sequence to function. | F31: Some fragile couplings, known and worked around. | G31: No reliance on incidental timing or order; couplings are explicit and robust.
A32: 3.5 | B32: Integration contracts testable independently | E32: Integrations can only be tested against live counterpart systems. | F32: Partially testable in isolation; some paths need the real counterpart. | G32: Contracts can be fully exercised with stubs, mocks, or simulators.
A33: 4. Modernisation — Can the language and code be brought forward?
A34: 4.1 | B34: Language/framework supported and hireable for | C34: G | E34: Language/framework is obsolete; hiring or retaining skills is a known problem. | F34: Supported but ageing; skills pool is shrinking or expensive. | G34: Current, actively supported, and readily hireable for.
A35: 4.2 | B35: Codebase structured so change is safe, not feared | E35: Change is feared; the team avoids touching it where possible. | F35: Change is possible but slow and carries known risk. | G35: Change is routine and made with confidence.
A36: 4.3 | B36: Toolchain can still pull current, patched components | E36: Toolchain is frozen; pulling current or patched dependencies is impossible or breaks the build. | F36: Toolchain works but is dated; updates are difficult. | G36: Toolchain is current and pulls patched dependencies cleanly.
A37: 4.4 | B37: Free of dead, unexplained code no one dares remove | E37: Significant dead or unexplained code that no one will remove. | F37: Some dead or unclear code, identified but not cleared. | G37: Codebase is clean; no significant dead or unexplained sections.
A38: 4.5 | B38: A section could be rewritten without reverse-engineering it | E38: Rewriting any section first requires reverse-engineering what it does. | F38: Rewritable from a mix of documentation and code reading. | G38: Behaviour is specified well enough to rewrite directly.
A39: 5. Embedded IP — Is critical bespoke logic buried and unextractable?
A40: 5.1 | B40: Bespoke logic documented to the standard of its complexity | C40: G | E40: Critical bespoke logic is undocumented; it exists only as code. | F40: Partially documented; documentation lags the code or covers only the simple parts. | G40: Documented proportionate to its complexity and kept current.
A41: 5.2 | B41: Logic isolated and identifiable, not smeared through general code | E41: Bespoke logic is smeared through the codebase; you cannot point to where it lives. | F41: Mostly identifiable, with some logic embedded in general-purpose code. | G41: Isolated, identifiable, and clearly delineated from general-purpose code.
A42: 5.3 | B42: The IP could be re-implemented from its specification | E42: No specification exists; the code is the only statement of the IP. | F42: A specification exists but is incomplete or partly out of date. | G42: A complete, current specification exists independent of the code.
...

Sheet Component 5
A1: Component Assessment — Component 5
A3: Component name | F3: Component rating | H3: =IF(COUNTIF(J6:J12,"RED")>0,"RED",IF(COUNTIF(J6:J12,"AMBER")>0,"AMBER",IF(COUNTIF(J6:J12,"GREEN")>0,"GREEN","—"))) -> —
A4: System / programme | F4: Lowest heading | H4: =IF(COUNTIF(J6:J12,"RED")>0,INDEX(F6:F12,MATCH("RED",J6:J12,0)),IF(COUNTIF(J6:J12,"AMBER")>0,INDEX(F6:F12,MATCH("AMBER",J6:J12,0)),IF(COUNTIF(J6:J12,"GREEN")>0,INDEX(F6:F12,MATCH("GREEN",J6:J12,0)),"—"))) -> —
A5: Owner (SRO or equivalent) | F5: Heading summary
A6: Assessor | F6: 1. Portability | I6: =IFERROR(ROUND(M15,2),"") | J6: =O15 -> —
A7: Assessment date | F7: 2. Modularity | I7: =IFERROR(ROUND(M16,2),"") | J7: =O16 -> —
A8: Mode | F8: 3. Integration | I8: =IFERROR(ROUND(M17,2),"") | J8: =O17 -> —
A9: Dependency classification | F9: 4. Modernisation | I9: =IFERROR(ROUND(M18,2),"") | J9: =O18 -> —
A10: Trajectory state | F10: 5. Embedded IP | I10: =IFERROR(ROUND(M19,2),"") | J10: =O19 -> —
A11: Previous assessment date | F11: 6. Knowledge Transferability | I11: =IFERROR(ROUND(M20,2),"") | J11: =O20 -> —
A12: Notes / context | F12: 7. Observability & Testability | I12: =IFERROR(ROUND(M21,2),"") | J12: =O21 -> —
A14: Test | B14: Test title | C14: G | D14: Score | E14: Anchor 1 | F14: Anchor 3 | G14: Anchor 5 | H14: Evidence status | I14: Evidence cited (what & where) | J14: Evidence owner | L14: HID | M14: Avg (non-gate) | N14: Min gate | O14: Rating
A15: 1. Portability — Can it be moved? | L15: 1 | M15: =IF(SUMPRODUCT((C16:C20<>"G")*ISNUMBER(D16:D20))=0,"",SUMPRODUCT((C16:C20<>"G")*ISNUMBER(D16:D20)*D16:D20)/SUMPRODUCT((C16:C20<>"G")*ISNUMBER(D16:D20))) | N15: =IF(MIN(IF(ISNUMBER(D16),D16,999))=999,"",MIN(IF(ISNUMBER(D16),D16,999))) | O15: =IF(M15="","—",IF(AND(ISNUMBER(N15),N15<=2),"RED",IF(M15>=4,"GREEN",IF(M15>=2.5,"AMBER","RED")))) -> —
A16: 1.1 | B16: Run on other infrastructure without redesign | C16: G | E16: Bound to its current host; moving it means a redesign. | F16: Movable to similar infrastructure with significant rework or constraints. | G16: Runs on alternative infrastructure with configuration changes only. | L16: 2 | M16: =IF(SUMPRODUCT((C22:C26<>"G")*ISNUMBER(D22:D26))=0,"",SUMPRODUCT((C22:C26<>"G")*ISNUMBER(D22:D26)*D22:D26)/SUMPRODUCT((C22:C26<>"G")*ISNUMBER(D22:D26))) | N16: =IF(MIN(IF(ISNUMBER(D23),D23,999))=999,"",MIN(IF(ISNUMBER(D23),D23,999))) | O16: =IF(M16="","—",IF(AND(ISNUMBER(N16),N16<=2),"RED",IF(M16>=4,"GREEN",IF(M16>=2.5,"AMBER","RED")))) -> —
A17: 1.2 | B17: Runtime dependencies current and supported | E17: Depends on out-of-support or end-of-life components. | F17: Mostly supported; some components near end-of-life or on extended support. | G17: All runtime dependencies are current and within their support lifecycle. | L17: 3 | M17: =IF(SUMPRODUCT((C28:C32<>"G")*ISNUMBER(D28:D32))=0,"",SUMPRODUCT((C28:C32<>"G")*ISNUMBER(D28:D32)*D28:D32)/SUMPRODUCT((C28:C32<>"G")*ISNUMBER(D28:D32))) | N17: =IF(MIN(IF(ISNUMBER(D30),D30,999))=999,"",MIN(IF(ISNUMBER(D30),D30,999))) | O17: =IF(M17="","—",IF(AND(ISNUMBER(N17),N17<=2),"RED",IF(M17>=4,"GREEN",IF(M17>=2.5,"AMBER","RED")))) -> —
A18: 1.3 | B18: Free of hard coupling to proprietary services or hardware | E18: Core function depends on proprietary services with no equivalent elsewhere. | F18: Uses proprietary services, but behind abstractions or with known alternatives. | G18: Uses portable, substitutable, or open interfaces throughout. | L18: 4 | M18: =IF(SUMPRODUCT((C34:C38<>"G")*ISNUMBER(D34:D38))=0,"",SUMPRODUCT((C34:C38<>"G")*ISNUMBER(D34:D38)*D34:D38)/SUMPRODUCT((C34:C38<>"G")*ISNUMBER(D34:D38))) | N18: =IF(MIN(IF(ISNUMBER(D34),D34,999))=999,"",MIN(IF(ISNUMBER(D34),D34,999))) | O18: =IF(M18="","—",IF(AND(ISNUMBER(N18),N18<=2),"RED",IF(M18>=4,"GREEN",IF(M18>=2.5,"AMBER","RED")))) -> —
A19: 1.4 | B19: Can be stood up from definition, not hand-built | E19: Environment exists only as a hand-built artefact; recreating it is reverse-engineering. | F19: Partially defined as code; some manual steps or tribal knowledge required. | G19: Fully reproducible from version-controlled definition. | L19: 5 | M19: =IF(SUMPRODUCT((C40:C44<>"G")*ISNUMBER(D40:D44))=0,"",SUMPRODUCT((C40:C44<>"G")*ISNUMBER(D40:D44)*D40:D44)/SUMPRODUCT((C40:C44<>"G")*ISNUMBER(D40:D44))) | N19: =IF(MIN(IF(ISNUMBER(D40),D40,999))=999,"",MIN(IF(ISNUMBER(D40),D40,999))) | O19: =IF(M19="","—",IF(AND(ISNUMBER(N19),N19<=2),"RED",IF(M19>=4,"GREEN",IF(M19>=2.5,"AMBER","RED")))) -> —
A20: 1.5 | B20: Data extractable and migratable without bespoke tooling | E20: Data is locked in a proprietary or undocumented store; extraction needs custom development. | F20: Extractable, but with effort, format conversion, or partial bespoke tooling. | G20: Stored in documented, standard formats; extractable with standard tools. | L20: 6 | M20: =IF(SUMPRODUCT((C46:C50<>"G")*ISNUMBER(D46:D50))=0,"",SUMPRODUCT((C46:C50<>"G")*ISNUMBER(D46:D50)*D46:D50)/SUMPRODUCT((C46:C50<>"G")*ISNUMBER(D46:D50))) | N20: =IF(MIN(IF(ISNUMBER(D46),D46,999))=999,"",MIN(IF(ISNUMBER(D46),D46,999))) | O20: =IF(M20="","—",IF(AND(ISNUMBER(N20),N20<=2),"RED",IF(M20>=4,"GREEN",IF(M20>=2.5,"AMBER","RED")))) -> —
A21: 2. Modularity — Can one part change without forcing the rest to change? | L21: 7 | M21: =IF(SUMPRODUCT((C52:C56<>"G")*ISNUMBER(D52:D56))=0,"",SUMPRODUCT((C52:C56<>"G")*ISNUMBER(D52:D56)*D52:D56)/SUMPRODUCT((C52:C56<>"G")*ISNUMBER(D52:D56))) | N21: =IF(MIN(IF(ISNUMBER(D52),D52,999),IF(ISNUMBER(D56),D56,999))=999,"",MIN(IF(ISNUMBER(D52),D52,999),IF(ISNUMBER(D56),D56,999))) | O21: =IF(M21="","—",IF(AND(ISNUMBER(N21),N21<=2),"RED",IF(M21>=4,"GREEN",IF(M21>=2.5,"AMBER","RED")))) -> —
A22: 2.1 | B22: Clearly bounded responsibilities | E22: Responsibilities are diffuse; no clear statement of what it does and does not own. | F22: Broadly bounded, but with overlaps or grey areas with other components. | G22: Clear, documented, single area of responsibility.
A23: 2.2 | B23: Can be developed, built and released independently | C23: G | E23: Cannot be built or released except as part of a larger coordinated effort. | F23: Independently buildable, but release is coupled to others in practice. | G23: Developed, built and released on its own cadence.
A24: 2.3 | B24: Internal parts separable, not rippling unpredictably | E24: Internally entangled; any change risks unpredictable effects elsewhere. | F24: Some internal structure; ripple is bounded but not fully predictable. | G24: Cleanly partitioned internally; change effects are localised and predictable.
A25: 2.4 | B25: Shared mutable state avoided or tightly controlled | E25: Shares mutable state freely; other components reach into its internals or vice versa. | F25: Some shared state, but mediated or documented. | G25: No uncontrolled shared state; interaction is through defined boundaries only.
